<sdf version='1.7'>
  <model name='hexa_urdf'>
    <link name='base_link'>
      <inertial>
        <pose>0.001026 -0.005086 -0.018805 0 -0 0</pose>
        <mass>1.67991</mass>
        <inertia>
          <ixx>0.00257193</ixx>
          <ixy>3.5543e-08</ixy>
          <ixz>1.67069e-09</ixz>
          <iyy>0.0025903</iyy>
          <iyz>6.41266e-08</iyz>
          <izz>0.00467567</izz>
        </inertia>
      </inertial>
      <collision name='base_link_collision'>
        <pose>0 0 0 0 -0 0</pose>
        <geometry>
          <mesh>
            <scale>1 1 1</scale>
            <uri>model://hexa_urdf/meshes/base_link.STL</uri>
          </mesh>
        </geometry>
      </collision>
      <visual name='base_link_visual'>
        <pose>0 0 0 0 -0 0</pose>
        <geometry>
          <mesh>
            <scale>1 1 1</scale>
            <uri>model://hexa_urdf/meshes/base_link.STL</uri>
          </mesh>
        </geometry>
      </visual>
    </link>
    <joint name='Propeller1_j' type='revolute'>
      <pose relative_to='base_link'>-0.127572 -0.220931 0.032508 1.5708 -0 0</pose>
      <parent>base_link</parent>
      <child>Propeller1</child>
      <axis>
        <xyz>0 1 0</xyz>
        <limit>
          <lower>-1e+16</lower>
          <upper>1e+16</upper>
        </limit>
        <dynamics>
          <spring_reference>0</spring_reference>
          <spring_stiffness>0</spring_stiffness>
        </dynamics>
      </axis>
    </joint>
    <link name='Propeller1'>
      <pose relative_to='Propeller1_j'>0 0 0 0 -0 0</pose>
      <inertial>
        <pose>-0 0.004397 -0 0 -0 0</pose>
        <mass>0.00751257</mass>
        <inertia>
          <ixx>1.74304e-05</ixx>
          <ixy>1.49738e-11</ixy>
          <ixz>-1.55538e-06</ixz>
          <iyy>1.77026e-05</iyy>
          <iyz>4.04499e-11</iyz>
          <izz>3.33965e-07</izz>
        </inertia>
      </inertial>
      <collision name='Propeller1_collision'>
        <pose>0 0 0 0 -0 0</pose>
        <geometry>
          <mesh>
            <scale>1 1 1</scale>
            <uri>model://hexa_urdf/meshes/Propeller1.STL</uri>
          </mesh>
        </geometry>
      </collision>
      <visual name='Propeller1_visual'>
        <pose>0 0 0 0 -0 0</pose>
        <geometry>
          <mesh>
            <scale>1 1 1</scale>
            <uri>model://hexa_urdf/meshes/Propeller1.STL</uri>
          </mesh>
        </geometry>
      </visual>
    </link>
    <joint name='Propeller2_j' type='revolute'>
      <pose relative_to='base_link'>-0.255118 1.5e-05 0.032508 1.5708 -0 0</pose>
      <parent>base_link</parent>
      <child>Propeller2</child>
      <axis>
        <xyz>0 1 0</xyz>
        <limit>
          <lower>-1e+16</lower>
          <upper>1e+16</upper>
        </limit>
        <dynamics>
          <spring_reference>0</spring_reference>
          <spring_stiffness>0</spring_stiffness>
        </dynamics>
      </axis>
    </joint>
    <link name='Propeller2'>
      <pose relative_to='Propeller2_j'>0 0 0 0 -0 0</pose>
      <inertial>
        <pose>-0 0.004397 -1e-06 0 -0 0</pose>
        <mass>0.00751264</mass>
        <inertia>
          <ixx>1.7431e-05</ixx>
          <ixy>1.49425e-11</ixy>
          <ixz>-1.55538e-06</ixz>
          <iyy>1.77031e-05</iyy>
          <iyz>2.91143e-11</iyz>
          <izz>3.33965e-07</izz>
        </inertia>
      </inertial>
      <collision name='Propeller2_collision'>
        <pose>0 0 0 0 -0 0</pose>
        <geometry>
          <mesh>
            <scale>1 1 1</scale>
            <uri>model://hexa_urdf/meshes/Propeller2.STL</uri>
          </mesh>
        </geometry>
      </collision>
      <visual name='Propeller2_visual'>
        <pose>0 0 0 0 -0 0</pose>
        <geometry>
          <mesh>
            <scale>1 1 1</scale>
            <uri>model://hexa_urdf/meshes/Propeller2.STL</uri>
          </mesh>
        </geometry>
      </visual>
    </link>
    <joint name='Propeller3_j' type='revolute'>
      <pose relative_to='base_link'>-0.127546 0.220947 0.032508 1.5708 -0 0</pose>
      <parent>base_link</parent>
      <child>Propeller3</child>
      <axis>
        <xyz>0 1 0</xyz>
        <limit>
          <lower>-1e+16</lower>
          <upper>1e+16</upper>
        </limit>
        <dynamics>
          <spring_reference>0</spring_reference>
          <spring_stiffness>0</spring_stiffness>
        </dynamics>
      </axis>
    </joint>
    <link name='Propeller3'>
      <pose relative_to='Propeller3_j'>0 0 0 0 -0 0</pose>
      <inertial>
        <pose>-0 0.004397 -1e-06 0 -0 0</pose>
        <mass>0.00751263</mass>
        <inertia>
          <ixx>1.7431e-05</ixx>
          <ixy>1.49387e-11</ixy>
          <ixz>-1.55538e-06</ixz>
          <iyy>1.77031e-05</iyy>
          <iyz>2.94871e-11</iyz>
          <izz>3.33965e-07</izz>
        </inertia>
      </inertial>
      <collision name='Propeller3_collision'>
        <pose>0 0 0 0 -0 0</pose>
        <geometry>
          <mesh>
            <scale>1 1 1</scale>
            <uri>model://hexa_urdf/meshes/Propeller3.STL</uri>
          </mesh>
        </geometry>
      </collision>
      <visual name='Propeller3_visual'>
        <pose>0 0 0 0 -0 0</pose>
        <geometry>
          <mesh>
            <scale>1 1 1</scale>
            <uri>model://hexa_urdf/meshes/Propeller3.STL</uri>
          </mesh>
        </geometry>
      </visual>
    </link>
    <joint name='Propeller4_j' type='revolute'>
      <pose relative_to='base_link'>0.12758 0.220925 0.032508 1.5708 -0 0.035332</pose>
      <parent>base_link</parent>
      <child>Propeller4</child>
      <axis>
        <xyz>0 1 0</xyz>
        <limit>
          <lower>-1e+16</lower>
          <upper>1e+16</upper>
        </limit>
        <dynamics>
          <spring_reference>0</spring_reference>
          <spring_stiffness>0</spring_stiffness>
        </dynamics>
      </axis>
    </joint>
    <link name='Propeller4'>
      <pose relative_to='Propeller4_j'>0 0 0 0 -0 0</pose>
      <inertial>
        <pose>-0 0.004397 -1e-06 0 -0 0</pose>
        <mass>0.00751252</mass>
        <inertia>
          <ixx>1.74299e-05</ixx>
          <ixy>1.49384e-11</ixy>
          <ixz>-1.55538e-06</ixz>
          <iyy>1.77021e-05</iyy>
          <iyz>2.91077e-11</iyz>
          <izz>3.33965e-07</izz>
        </inertia>
      </inertial>
      <collision name='Propeller4_collision'>
        <pose>0 0 0 0 -0 0</pose>
        <geometry>
          <mesh>
            <scale>1 1 1</scale>
            <uri>model://hexa_urdf/meshes/Propeller4.STL</uri>
          </mesh>
        </geometry>
      </collision>
      <visual name='Propeller4_visual'>
        <pose>0 0 0 0 -0 0</pose>
        <geometry>
          <mesh>
            <scale>1 1 1</scale>
            <uri>model://hexa_urdf/meshes/Propeller4.STL</uri>
          </mesh>
        </geometry>
      </visual>
    </link>
    <joint name='Propeller5_j' type='revolute'>
      <pose relative_to='base_link'>0.255118 -1.5e-05 0.032508 1.5708 -0 0</pose>
      <parent>base_link</parent>
      <child>Propeller5</child>
      <axis>
        <xyz>0 1 0</xyz>
        <limit>
          <lower>-1e+16</lower>
          <upper>1e+16</upper>
        </limit>
        <dynamics>
          <spring_reference>0</spring_reference>
          <spring_stiffness>0</spring_stiffness>
        </dynamics>
      </axis>
    </joint>
    <link name='Propeller5'>
      <pose relative_to='Propeller5_j'>0 0 0 0 -0 0</pose>
      <inertial>
        <pose>-0 0.004397 -1e-06 0 -0 0</pose>
        <mass>0.00751264</mass>
        <inertia>
          <ixx>1.7431e-05</ixx>
          <ixy>1.49425e-11</ixy>
          <ixz>-1.55538e-06</ixz>
          <iyy>1.77031e-05</iyy>
          <iyz>2.91143e-11</iyz>
          <izz>3.33965e-07</izz>
        </inertia>
      </inertial>
      <collision name='Propeller5_collision'>
        <pose>0 0 0 0 -0 0</pose>
        <geometry>
          <mesh>
            <scale>1 1 1</scale>
            <uri>model://hexa_urdf/meshes/Propeller5.STL</uri>
          </mesh>
        </geometry>
      </collision>
      <visual name='Propeller5_visual'>
        <pose>0 0 0 0 -0 0</pose>
        <geometry>
          <mesh>
            <scale>1 1 1</scale>
            <uri>model://hexa_urdf/meshes/Propeller5.STL</uri>
          </mesh>
        </geometry>
      </visual>
    </link>
    <joint name='Propeller6_j' type='revolute'>
      <pose relative_to='base_link'>0.12755 -0.22095 0.032508 1.5708 -0 0</pose>
      <parent>base_link</parent>
      <child>Propeller6</child>
      <axis>
        <xyz>0 1 0</xyz>
        <limit>
          <lower>-1e+16</lower>
          <upper>1e+16</upper>
        </limit>
        <dynamics>
          <spring_reference>0</spring_reference>
          <spring_stiffness>0</spring_stiffness>
        </dynamics>
      </axis>
    </joint>
    <link name='Propeller6'>
      <pose relative_to='Propeller6_j'>0 0 0 0 -0 0</pose>
      <inertial>
        <pose>-0 0.004397 -1e-06 0 -0 0</pose>
        <mass>0.00751263</mass>
        <inertia>
          <ixx>1.7431e-05</ixx>
          <ixy>1.49393e-11</ixy>
          <ixz>-1.55538e-06</ixz>
          <iyy>1.77031e-05</iyy>
          <iyz>2.94878e-11</iyz>
          <izz>3.33965e-07</izz>
        </inertia>
      </inertial>
      <collision name='Propeller6_collision'>
        <pose>0 0 0 0 -0 0</pose>
        <geometry>
          <mesh>
            <scale>1 1 1</scale>
            <uri>model://hexa_urdf/meshes/Propeller6.STL</uri>
          </mesh>
        </geometry>
      </collision>
      <visual name='Propeller6_visual'>
        <pose>0 0 0 0 -0 0</pose>
        <geometry>
          <mesh>
            <scale>1 1 1</scale>
            <uri>model://hexa_urdf/meshes/Propeller6.STL</uri>
          </mesh>
        </geometry>
      </visual>
    </link>
  </model>
</sdf>
